Workbook

Sheet contracts
A1: Name | B1: KOL_ID | C1: Area | D1: Country | E1: Contract Value(USD) | F1: Contract Start | G1: Contract End | H1: Days Left | I1: Task | J1: Activity | K1: Times | L1: Frequency | M1: Lat | N1: Lon
A2: Dr. Robert Jung | B2: 101001 | C2: Europe | D2: UK | F2: 45758 | G2: 46022 | H2: =IF(ISBLANK(G2), "", IF(INT(G2 - TODAY()) >= 0, "D-" & INT(G2 - TODAY()), "D+" & ABS(INT(G2 - TODAY())))) -> D-44 | I2: Lecture | J2: offline lecture | K2: per quarter | L2: {=_xlfn.IFS(OR(ISBLANK(F2), ISBLANK(G2), ISBLANK(K2)), "", K2="per quarter", (ROUNDUP(MONTH(G2)/3,0) - ROUNDUP(MONTH(F2)/3,0)) + (YEAR(G2) - YEAR(F2)) * 4 + 1, K2="per month", (MONTH(G2) - MONTH(F2)) + (YEAR(G2) - YEAR(F2)) * 12 + 1, K2="bimonthly", ROUNDUP(((MONTH(G2) - MONTH(F2)) + (YEAR(G2) - YEAR(F2)) * 12 + 1) / 2, 0), K2="per year", (YEAR(G2) - YEAR(F2)) + 1, K2="biyear", ROUNDUP(((YEAR(G2) - YEAR(F2)) + 1) / 2, 0), TRUE, "")} -> 3 | M2: -3.435973 | N2: 55.378051
A3: Dr. Filip Rebelo | B3: 102001 | C3: Europe | D3: Sweden | F3: 45757 | G3: 46022 | H3: =IF(ISBLANK(G3), "", IF(INT(G3 - TODAY()) >= 0, "D-" & INT(G3 - TODAY()), "D+" & ABS(INT(G3 - TODAY())))) -> D-44 | I3: Lecture | J3: offline lecture | K3: per quarter | L3: {=_xlfn.IFS(OR(ISBLANK(F3), ISBLANK(G3), ISBLANK(K3)), "", K3="per quarter", (ROUNDUP(MONTH(G3)/3,0) - ROUNDUP(MONTH(F3)/3,0)) + (YEAR(G3) - YEAR(F3)) * 4 + 1, K3="per month", (MONTH(G3) - MONTH(F3)) + (YEAR(G3) - YEAR(F3)) * 12 + 1, K3="bimonthly", ROUNDUP(((MONTH(G3) - MONTH(F3)) + (YEAR(G3) - YEAR(F3)) * 12 + 1) / 2, 0), K3="per year", (YEAR(G3) - YEAR(F3)) + 1, K3="biyear", ROUNDUP(((YEAR(G3) - YEAR(F3)) + 1) / 2, 0), TRUE, "")} -> 3 | M3: 13.004927 | N3: 55.604807
A4: Dr. Filip Rebelo | B4: 102001 | C4: Europe | D4: Sweden | F4: 45757 | G4: 46022 | H4: =IF(ISBLANK(G4), "", IF(INT(G4 - TODAY()) >= 0, "D-" & INT(G4 - TODAY()), "D+" & ABS(INT(G4 - TODAY())))) -> D-44 | I4: Case Report | J4: Article case | K4: per year | L4: {=_xlfn.IFS(OR(ISBLANK(F4), ISBLANK(G4), ISBLANK(K4)), "", K4="per quarter", (ROUNDUP(MONTH(G4)/3,0) - ROUNDUP(MONTH(F4)/3,0)) + (YEAR(G4) - YEAR(F4)) * 4 + 1, K4="per month", (MONTH(G4) - MONTH(F4)) + (YEAR(G4) - YEAR(F4)) * 12 + 1, K4="bimonthly", ROUNDUP(((MONTH(G4) - MONTH(F4)) + (YEAR(G4) - YEAR(F4)) * 12 + 1) / 2, 0), K4="per year", (YEAR(G4) - YEAR(F4)) + 1, K4="biyear", ROUNDUP(((YEAR(G4) - YEAR(F4)) + 1) / 2, 0), TRUE, "")} -> 1 | M4: 13.004927 | N4: 55.604807
A5: Dr. Alexandre Richard | B5: 103001 | C5: Europe | D5: France | F5: 45764 | G5: 46022 | H5: =IF(ISBLANK(G5), "", IF(INT(G5 - TODAY()) >= 0, "D-" & INT(G5 - TODAY()), "D+" & ABS(INT(G5 - TODAY())))) -> D-44 | I5: Webinar | J5: Webinar | K5: per year | L5: {=_xlfn.IFS(OR(ISBLANK(F5), ISBLANK(G5), ISBLANK(K5)), "", K5="per quarter", (ROUNDUP(MONTH(G5)/3,0) - ROUNDUP(MONTH(F5)/3,0)) + (YEAR(G5) - YEAR(F5)) * 4 + 1, K5="per month", (MONTH(G5) - MONTH(F5)) + (YEAR(G5) - YEAR(F5)) * 12 + 1, K5="bimonthly", ROUNDUP(((MONTH(G5) - MONTH(F5)) + (YEAR(G5) - YEAR(F5)) * 12 + 1) / 2, 0), K5="per year", (YEAR(G5) - YEAR(F5)) + 1, K5="biyear", ROUNDUP(((YEAR(G5) - YEAR(F5)) + 1) / 2, 0), TRUE, "")} -> 1 | M5: 2.3513765 | N5: 48.857548
A6: Dr. Alexandre Richard | B6: 103001 | C6: Europe | D6: France | F6: 45764 | G6: 46022 | H6: =IF(ISBLANK(G6), "", IF(INT(G6 - TODAY()) >= 0, "D-" & INT(G6 - TODAY()), "D+" & ABS(INT(G6 - TODAY())))) -> D-44 | I6: Lecture | J6: ADF Lecture | K6: per year | L6: {=_xlfn.IFS(OR(ISBLANK(F6), ISBLANK(G6), ISBLANK(K6)), "", K6="per quarter", (ROUNDUP(MONTH(G6)/3,0) - ROUNDUP(MONTH(F6)/3,0)) + (YEAR(G6) - YEAR(F6)) * 4 + 1, K6="per month", (MONTH(G6) - MONTH(F6)) + (YEAR(G6) - YEAR(F6)) * 12 + 1, K6="bimonthly", ROUNDUP(((MONTH(G6) - MONTH(F6)) + (YEAR(G6) - YEAR(F6)) * 12 + 1) / 2, 0), K6="per year", (YEAR(G6) - YEAR(F6)) + 1, K6="biyear", ROUNDUP(((YEAR(G6) - YEAR(F6)) + 1) / 2, 0), TRUE, "")} -> 1 | M6: 2.3513765 | N6: 48.857548
A7: Dr. Alexandre Richard | B7: 103001 | C7: Europe | D7: France | F7: 45764 | G7: 46022 | H7: =IF(ISBLANK(G7), "", IF(INT(G7 - TODAY()) >= 0, "D-" & INT(G7 - TODAY()), "D+" & ABS(INT(G7 - TODAY())))) -> D-44 | I7: SNS Posting | J7: social activities | K7: per year | L7: {=_xlfn.IFS(OR(ISBLANK(F7), ISBLANK(G7), ISBLANK(K7)), "", K7="per quarter", (ROUNDUP(MONTH(G7)/3,0) - ROUNDUP(MONTH(F7)/3,0)) + (YEAR(G7) - YEAR(F7)) * 4 + 1, K7="per month", (MONTH(G7) - MONTH(F7)) + (YEAR(G7) - YEAR(F7)) * 12 + 1, K7="bimonthly", ROUNDUP(((MONTH(G7) - MONTH(F7)) + (YEAR(G7) - YEAR(F7)) * 12 + 1) / 2, 0), K7="per year", (YEAR(G7) - YEAR(F7)) + 1, K7="biyear", ROUNDUP(((YEAR(G7) - YEAR(F7)) + 1) / 2, 0), TRUE, "")} -> 1 | M7: 2.3513765 | N7: 48.857548
A8: Dr. Gary Finelle | B8: 103002 | C8: Europe | D8: France | H8: =IF(ISBLANK(G8), "", IF(INT(G8 - TODAY()) >= 0, "D-" & INT(G8 - TODAY()), "D+" & ABS(INT(G8 - TODAY())))) | I8: R&D Feedback | J8: R&D Feedback | K8: per year | L8: {=_xlfn.IFS(OR(ISBLANK(F8), ISBLANK(G8), ISBLANK(K8)), "", K8="per quarter", (ROUNDUP(MONTH(G8)/3,0) - ROUNDUP(MONTH(F8)/3,0)) + (YEAR(G8) - YEAR(F8)) * 4 + 1, K8="per month", (MONTH(G8) - MONTH(F8)) + (YEAR(G8) - YEAR(F8)) * 12 + 1, K8="bimonthly", ROUNDUP(((MONTH(G8) - MONTH(F8)) + (YEAR(G8) - YEAR(F8)) * 12 + 1) / 2, 0), K8="per year", (YEAR(G8) - YEAR(F8)) + 1, K8="biyear", ROUNDUP(((YEAR(G8) - YEAR(F8)) + 1) / 2, 0), TRUE, "")} | M8: 2.3011467 | N8: 48.857299
A9: Dr. Gary Finelle | B9: 103002 | C9: Europe | D9: France | H9: =IF(ISBLANK(G9), "", IF(INT(G9 - TODAY()) >= 0, "D-" & INT(G9 - TODAY()), "D+" & ABS(INT(G9 - TODAY())))) | I9: Case Report | J9: Case | K9: per year | L9: {=_xlfn.IFS(OR(ISBLANK(F9), ISBLANK(G9), ISBLANK(K9)), "", K9="per quarter", (ROUNDUP(MONTH(G9)/3,0) - ROUNDUP(MONTH(F9)/3,0)) + (YEAR(G9) - YEAR(F9)) * 4 + 1, K9="per month", (MONTH(G9) - MONTH(F9)) + (YEAR(G9) - YEAR(F9)) * 12 + 1, K9="bimonthly", ROUNDUP(((MONTH(G9) - MONTH(F9)) + (YEAR(G9) - YEAR(F9)) * 12 + 1) / 2, 0), K9="per year", (YEAR(G9) - YEAR(F9)) + 1, K9="biyear", ROUNDUP(((YEAR(G9) - YEAR(F9)) + 1) / 2, 0), TRUE, "")} | M9: 2.3011467 | N9: 48.857299
A10: Dr. Gary Finelle | B10: 103002 | C10: Europe | D10: France | H10: =IF(ISBLANK(G10), "", IF(INT(G10 - TODAY()) >= 0, "D-" & INT(G10 - TODAY()), "D+" & ABS(INT(G10 - TODAY())))) | I10: (Other) | J10: Contents creation | K10: per year | L10: {=_xlfn.IFS(OR(ISBLANK(F10), ISBLANK(G10), ISBLANK(K10)), "", K10="per quarter", (ROUNDUP(MONTH(G10)/3,0) - ROUNDUP(MONTH(F10)/3,0)) + (YEAR(G10) - YEAR(F10)) * 4 + 1, K10="per month", (MONTH(G10) - MONTH(F10)) + (YEAR(G10) - YEAR(F10)) * 12 + 1, K10="bimonthly", ROUNDUP(((MONTH(G10) - MONTH(F10)) + (YEAR(G10) - YEAR(F10)) * 12 + 1) / 2, 0), K10="per year", (YEAR(G10) - YEAR(F10)) + 1, K10="biyear", ROUNDUP(((YEAR(G10) - YEAR(F10)) + 1) / 2, 0), TRUE, "")} | M10: 2.3011467 | N10: 48.857299
A11: Dr. Gary Finelle | B11: 103002 | C11: Europe | D11: France | H11: =IF(ISBLANK(G11), "", IF(INT(G11 - TODAY()) >= 0, "D-" & INT(G11 - TODAY()), "D+" & ABS(INT(G11 - TODAY())))) | I11: Lecture | J11: Academy lectures | K11: per year | L11: {=_xlfn.IFS(OR(ISBLANK(F11), ISBLANK(G11), ISBLANK(K11)), "", K11="per quarter", (ROUNDUP(MONTH(G11)/3,0) - ROUNDUP(MONTH(F11)/3,0)) + (YEAR(G11) - YEAR(F11)) * 4 + 1, K11="per month", (MONTH(G11) - MONTH(F11)) + (YEAR(G11) - YEAR(F11)) * 12 + 1, K11="bimonthly", ROUNDUP(((MONTH(G11) - MONTH(F11)) + (YEAR(G11) - YEAR(F11)) * 12 + 1) / 2, 0), K11="per year", (YEAR(G11) - YEAR(F11)) + 1, K11="biyear", ROUNDUP(((YEAR(G11) - YEAR(F11)) + 1) / 2, 0), TRUE, "")} | M11: 2.3011467 | N11: 48.857299
A12: Dr. Pierre Leclercq | B12: 103003 | C12: Europe | D12: France | H12: =IF(ISBLANK(G12), "", IF(INT(G12 - TODAY()) >= 0, "D-" & INT(G12 - TODAY()), "D+" & ABS(INT(G12 - TODAY())))) | I12: R&D Feedback | J12: R&D Feedback | K12: per year | L12: {=_xlfn.IFS(OR(ISBLANK(F12), ISBLANK(G12), ISBLANK(K12)), "", K12="per quarter", (ROUNDUP(MONTH(G12)/3,0) - ROUNDUP(MONTH(F12)/3,0)) + (YEAR(G12) - YEAR(F12)) * 4 + 1, K12="per month", (MONTH(G12) - MONTH(F12)) + (YEAR(G12) - YEAR(F12)) * 12 + 1, K12="bimonthly", ROUNDUP(((MONTH(G12) - MONTH(F12)) + (YEAR(G12) - YEAR(F12)) * 12 + 1) / 2, 0), K12="per year", (YEAR(G12) - YEAR(F12)) + 1, K12="biyear", ROUNDUP(((YEAR(G12) - YEAR(F12)) + 1) / 2, 0), TRUE, "")} | M12: 4.9800614 | N12: 43.403449
A13: Dr. Pierre Leclercq | B13: 103003 | C13: Europe | D13: France | H13: =IF(ISBLANK(G13), "", IF(INT(G13 - TODAY()) >= 0, "D-" & INT(G13 - TODAY()), "D+" & ABS(INT(G13 - TODAY())))) | I13: Case Report | J13: Case | K13: per year | L13: {=_xlfn.IFS(OR(ISBLANK(F13), ISBLANK(G13), ISBLANK(K13)), "", K13="per quarter", (ROUNDUP(MONTH(G13)/3,0) - ROUNDUP(MONTH(F13)/3,0)) + (YEAR(G13) - YEAR(F13)) * 4 + 1, K13="per month", (MONTH(G13) - MONTH(F13)) + (YEAR(G13) - YEAR(F13)) * 12 + 1, K13="bimonthly", ROUNDUP(((MONTH(G13) - MONTH(F13)) + (YEAR(G13) - YEAR(F13)) * 12 + 1) / 2, 0), K13="per year", (YEAR(G13) - YEAR(F13)) + 1, K13="biyear", ROUNDUP(((YEAR(G13) - YEAR(F13)) + 1) / 2, 0), TRUE, "")} | M13: 4.9800614 | N13: 43.403449
A14: Dr. Pierre Leclercq | B14: 103003 | C14: Europe | D14: France | H14: =IF(ISBLANK(G14), "", IF(INT(G14 - TODAY()) >= 0, "D-" & INT(G14 - TODAY()), "D+" & ABS(INT(G14 - TODAY())))) | I14: (Other) | J14: Contents creation | K14: per year | L14: {=_xlfn.IFS(OR(ISBLANK(F14), ISBLANK(G14), ISBLANK(K14)), "", K14="per quarter", (ROUNDUP(MONTH(G14)/3,0) - ROUNDUP(MONTH(F14)/3,0)) + (YEAR(G14) - YEAR(F14)) * 4 + 1, K14="per month", (MONTH(G14) - MONTH(F14)) + (YEAR(G14) - YEAR(F14)) * 12 + 1, K14="bimonthly", ROUNDUP(((MONTH(G14) - MONTH(F14)) + (YEAR(G14) - YEAR(F14)) * 12 + 1) / 2, 0), K14="per year", (YEAR(G14) - YEAR(F14)) + 1, K14="biyear", ROUNDUP(((YEAR(G14) - YEAR(F14)) + 1) / 2, 0), TRUE, "")} | M14: 4.9800614 | N14: 43.403449
A15: Dr. Pierre Leclercq | B15: 103003 | C15: Europe | D15: France | H15: =IF(ISBLANK(G15), "", IF(INT(G15 - TODAY()) >= 0, "D-" & INT(G15 - TODAY()), "D+" & ABS(INT(G15 - TODAY())))) | I15: Lecture | J15: Academy lectures | K15: per year | L15: {=_xlfn.IFS(OR(ISBLANK(F15), ISBLANK(G15), ISBLANK(K15)), "", K15="per quarter", (ROUNDUP(MONTH(G15)/3,0) - ROUNDUP(MONTH(F15)/3,0)) + (YEAR(G15) - YEAR(F15)) * 4 + 1, K15="per month", (MONTH(G15) - MONTH(F15)) + (YEAR(G15) - YEAR(F15)) * 12 + 1, K15="bimonthly", ROUNDUP(((MONTH(G15) - MONTH(F15)) + (YEAR(G15) - YEAR(F15)) * 12 + 1) / 2, 0), K15="per year", (YEAR(G15) - YEAR(F15)) + 1, K15="biyear", ROUNDUP(((YEAR(G15) - YEAR(F15)) + 1) / 2, 0), TRUE, "")} | M15: 4.9800614 | N15: 43.403449
A16: Dr. Emmanuel Bocquet | B16: 103004 | C16: Europe | D16: France | F16: 45757 | G16: 46022 | H16: =IF(ISBLANK(G16), "", IF(INT(G16 - TODAY()) >= 0, "D-" & INT(G16 - TODAY()), "D+" & ABS(INT(G16 - TODAY())))) -> D-44 | I16: Case Report | J16: Cases | K16: per quarter | L16: {=_xlfn.IFS(OR(ISBLANK(F16), ISBLANK(G16), ISBLANK(K16)), "", K16="per quarter", (ROUNDUP(MONTH(G16)/3,0) - ROUNDUP(MONTH(F16)/3,0)) + (YEAR(G16) - YEAR(F16)) * 4 + 1, K16="per month", (MONTH(G16) - MONTH(F16)) + (YEAR(G16) - YEAR(F16)) * 12 + 1, K16="bimonthly", ROUNDUP(((MONTH(G16) - MONTH(F16)) + (YEAR(G16) - YEAR(F16)) * 12 + 1) / 2, 0), K16="per year", (YEAR(G16) - YEAR(F16)) + 1, K16="biyear", ROUNDUP(((YEAR(G16) - YEAR(F16)) + 1) / 2, 0), TRUE, "")} -> 3 | M16: 3.0395183 | N16: 50.623741
A17: Dr. Emmanuel Bocquet | B17: 103004 | C17: Europe | D17: France | F17: 45757 | G17: 46022 | H17: =IF(ISBLANK(G17), "", IF(INT(G17 - TODAY()) >= 0, "D-" & INT(G17 - TODAY()), "D+" & ABS(INT(G17 - TODAY())))) -> D-44 | I17: Lecture | J17: ADF speaker | K17: per year | L17: {=_xlfn.IFS(OR(ISBLANK(F17), ISBLANK(G17), ISBLANK(K17)), "", K17="per quarter", (ROUNDUP(MONTH(G17)/3,0) - ROUNDUP(MONTH(F17)/3,0)) + (YEAR(G17) - YEAR(F17)) * 4 + 1, K17="per month", (MONTH(G17) - MONTH(F17)) + (YEAR(G17) - YEAR(F17)) * 12 + 1, K17="bimonthly", ROUNDUP(((MONTH(G17) - MONTH(F17)) + (YEAR(G17) - YEAR(F17)) * 12 + 1) / 2, 0), K17="per year", (YEAR(G17) - YEAR(F17)) + 1, K17="biyear", ROUNDUP(((YEAR(G17) - YEAR(F17)) + 1) / 2, 0), TRUE, "")} -> 1 | M17: 3.0395183 | N17: 50.623741
A18: Dr. Emmanuel Bocquet | B18: 103004 | C18: Europe | D18: France | F18: 45757 | G18: 46022 | H18: =IF(ISBLANK(G18), "", IF(INT(G18 - TODAY()) >= 0, "D-" & INT(G18 - TODAY()), "D+" & ABS(INT(G18 - TODAY())))) -> D-44 | I18: Webinar | J18: Webinar | K18: per year | L18: {=_xlfn.IFS(OR(ISBLANK(F18), ISBLANK(G18), ISBLANK(K18)), "", K18="per quarter", (ROUNDUP(MONTH(G18)/3,0) - ROUNDUP(MONTH(F18)/3,0)) + (YEAR(G18) - YEAR(F18)) * 4 + 1, K18="per month", (MONTH(G18) - MONTH(F18)) + (YEAR(G18) - YEAR(F18)) * 12 + 1, K18="bimonthly", ROUNDUP(((MONTH(G18) - MONTH(F18)) + (YEAR(G18) - YEAR(F18)) * 12 + 1) / 2, 0), K18="per year", (YEAR(G18) - YEAR(F18)) + 1, K18="biyear", ROUNDUP(((YEAR(G18) - YEAR(F18)) + 1) / 2, 0), TRUE, "")} -> 1 | M18: 3.0395183 | N18: 50.623741
A19: Dr. Emmanuel Bocquet | B19: 103004 | C19: Europe | D19: France | F19: 45757 | G19: 46022 | H19: =IF(ISBLANK(G19), "", IF(INT(G19 - TODAY()) >= 0, "D-" & INT(G19 - TODAY()), "D+" & ABS(INT(G19 - TODAY())))) -> D-44 | I19: SNS Posting | J19: Social engagement | K19: per year | L19: {=_xlfn.IFS(OR(ISBLANK(F19), ISBLANK(G19), ISBLANK(K19)), "", K19="per quarter", (ROUNDUP(MONTH(G19)/3,0) - ROUNDUP(MONTH(F19)/3,0)) + (YEAR(G19) - YEAR(F19)) * 4 + 1, K19="per month", (MONTH(G19) - MONTH(F19)) + (YEAR(G19) - YEAR(F19)) * 12 + 1, K19="bimonthly", ROUNDUP(((MONTH(G19) - MONTH(F19)) + (YEAR(G19) - YEAR(F19)) * 12 + 1) / 2, 0), K19="per year", (YEAR(G19) - YEAR(F19)) + 1, K19="biyear", ROUNDUP(((YEAR(G19) - YEAR(F19)) + 1) / 2, 0), TRUE, "")} -> 1 | M19: 3.0395183 | N19: 50.623741
A20: Dr. Oguz Emeklibas | B20: 104001 | C20: Europe | D20: Germany | F20: 45839 | G20: 46204 | H20: =IF(ISBLANK(G20), "", IF(INT(G20 - TODAY()) >= 0, "D-" & INT(G20 - TODAY()), "D+" & ABS(INT(G20 - TODAY())))) -> D-226 | I20: Case Report | J20: Cases | K20: per year | L20: {=_xlfn.IFS(OR(ISBLANK(F20), ISBLANK(G20), ISBLANK(K20)), "", K20="per quarter", (ROUNDUP(MONTH(G20)/3,0) - ROUNDUP(MONTH(F20)/3,0)) + (YEAR(G20) - YEAR(F20)) * 4 + 1, K20="per month", (MONTH(G20) - MONTH(F20)) + (YEAR(G20) - YEAR(F20)) * 12 + 1, K20="bimonthly", ROUNDUP(((MONTH(G20) - MONTH(F20)) + (YEAR(G20) - YEAR(F20)) * 12 + 1) / 2, 0), K20="per year", (YEAR(G20) - YEAR(F20)) + 1, K20="biyear", ROUNDUP(((YEAR(G20) - YEAR(F20)) + 1) / 2, 0), TRUE, "")} -> 2 | M20: 8.4041959 | N20: 49.517973
A21: Dr. Oguz Emeklibas | B21: 104001 | C21: Europe | D21: Germany | F21: 45839 | G21: 46204 | H21: =IF(ISBLANK(G21), "", IF(INT(G21 - TODAY()) >= 0, "D-" & INT(G21 - TODAY()), "D+" & ABS(INT(G21 - TODAY())))) -> D-226 | I21: Lecture | J21: Lecture | K21: per year | L21: {=_xlfn.IFS(OR(ISBLANK(F21), ISBLANK(G21), ISBLANK(K21)), "", K21="per quarter", (ROUNDUP(MONTH(G21)/3,0) - ROUNDUP(MONTH(F21)/3,0)) + (YEAR(G21) - YEAR(F21)) * 4 + 1, K21="per month", (MONTH(G21) - MONTH(F21)) + (YEAR(G21) - YEAR(F21)) * 12 + 1, K21="bimonthly", ROUNDUP(((MONTH(G21) - MONTH(F21)) + (YEAR(G21) - YEAR(F21)) * 12 + 1) / 2, 0), K21="per year", (YEAR(G21) - YEAR(F21)) + 1, K21="biyear", ROUNDUP(((YEAR(G21) - YEAR(F21)) + 1) / 2, 0), TRUE, "")} -> 2 | M21: 8.4041959 | N21: 49.517973
A22: Dr. Oguz Emeklibas | B22: 104001 | C22: Europe | D22: Germany | F22: 45839 | G22: 46204 | H22: =IF(ISBLANK(G22), "", IF(INT(G22 - TODAY()) >= 0, "D-" & INT(G22 - TODAY()), "D+" & ABS(INT(G22 - TODAY())))) -> D-226 | I22: SNS Posting | J22: Social Media | K22: per year | L22: {=_xlfn.IFS(OR(ISBLANK(F22), ISBLANK(G22), ISBLANK(K22)), "", K22="per quarter", (ROUNDUP(MONTH(G22)/3,0) - ROUNDUP(MONTH(F22)/3,0)) + (YEAR(G22) - YEAR(F22)) * 4 + 1, K22="per month", (MONTH(G22) - MONTH(F22)) + (YEAR(G22) - YEAR(F22)) * 12 + 1, K22="bimonthly", ROUNDUP(((MONTH(G22) - MONTH(F22)) + (YEAR(G22) - YEAR(F22)) * 12 + 1) / 2, 0), K22="per year", (YEAR(G22) - YEAR(F22)) + 1, K22="biyear", ROUNDUP(((YEAR(G22) - YEAR(F22)) + 1) / 2, 0), TRUE, "")} -> 2 | M22: 8.4041959 | N22: 49.517973
A23: Dr. Frank Maier | B23: 104002 | C23: Europe | D23: Germany | H23: =IF(ISBLANK(G23), "", IF(INT(G23 - TODAY()) >= 0, "D-" & INT(G23 - TODAY()), "D+" & ABS(INT(G23 - TODAY())))) | I23: R&D Feedback | J23: R&D Feedback | K23: per year | L23: {=_xlfn.IFS(OR(ISBLANK(F23), ISBLANK(G23), ISBLANK(K23)), "", K23="per quarter", (ROUNDUP(MONTH(G23)/3,0) - ROUNDUP(MONTH(F23)/3,0)) + (YEAR(G23) - YEAR(F23)) * 4 + 1, K23="per month", (MONTH(G23) - MONTH(F23)) + (YEAR(G23) - YEAR(F23)) * 12 + 1, K23="bimonthly", ROUNDUP(((MONTH(G23) - MONTH(F23)) + (YEAR(G23) - YEAR(F23)) * 12 + 1) / 2, 0), K23="per year", (YEAR(G23) - YEAR(F23)) + 1, K23="biyear", ROUNDUP(((YEAR(G23) - YEAR(F23)) + 1) / 2, 0), TRUE, "")} | M23: 9.0599564 | N23: 48.509597
A24: Dr. Frank Maier | B24: 104002 | C24: Europe | D24: Germany | H24: =IF(ISBLANK(G24), "", IF(INT(G24 - TODAY()) >= 0, "D-" & INT(G24 - TODAY()), "D+" & ABS(INT(G24 - TODAY())))) | I24: Case Report | J24: Case | K24: per year | L24: {=_xlfn.IFS(OR(ISBLANK(F24), ISBLANK(G24), ISBLANK(K24)), "", K24="per quarter", (ROUNDUP(MONTH(G24)/3,0) - ROUNDUP(MONTH(F24)/3,0)) + (YEAR(G24) - YEAR(F24)) * 4 + 1, K24="per month", (MONTH(G24) - MONTH(F24)) + (YEAR(G24) - YEAR(F24)) * 12 + 1, K24="bimonthly", ROUNDUP(((MONTH(G24) - MONTH(F24)) + (YEAR(G24) - YEAR(F24)) * 12 + 1) / 2, 0), K24="per year", (YEAR(G24) - YEAR(F24)) + 1, K24="biyear", ROUNDUP(((YEAR(G24) - YEAR(F24)) + 1) / 2, 0), TRUE, "")} | M24: 9.0599564 | N24: 48.509597
A25: Dr. Frank Maier | B25: 104002 | C25: Europe | D25: Germany | H25: =IF(ISBLANK(G25), "", IF(INT(G25 - TODAY()) >= 0, "D-" & INT(G25 - TODAY()), "D+" & ABS(INT(G25 - TODAY())))) | I25: (Other) | J25: Contents creation | K25: per year | L25: {=_xlfn.IFS(OR(ISBLANK(F25), ISBLANK(G25), ISBLANK(K25)), "", K25="per quarter", (ROUNDUP(MONTH(G25)/3,0) - ROUNDUP(MONTH(F25)/3,0)) + (YEAR(G25) - YEAR(F25)) * 4 + 1, K25="per month", (MONTH(G25) - MONTH(F25)) + (YEAR(G25) - YEAR(F25)) * 12 + 1, K25="bimonthly", ROUNDUP(((MONTH(G25) - MONTH(F25)) + (YEAR(G25) - YEAR(F25)) * 12 + 1) / 2, 0), K25="per year", (YEAR(G25) - YEAR(F25)) + 1, K25="biyear", ROUNDUP(((YEAR(G25) - YEAR(F25)) + 1) / 2, 0), TRUE, "")} | M25: 9.0599564 | N25: 48.509597
A26: Dr. Frank Maier | B26: 104002 | C26: Europe | D26: Germany | H26: =IF(ISBLANK(G26), "", IF(INT(G26 - TODAY()) >= 0, "D-" & INT(G26 - TODAY()), "D+" & ABS(INT(G26 - TODAY())))) | I26: Lecture | J26: Academy lectures | K26: per year | L26: {=_xlfn.IFS(OR(ISBLANK(F26), ISBLANK(G26), ISBLANK(K26)), "", K26="per quarter", (ROUNDUP(MONTH(G26)/3,0) - ROUNDUP(MONTH(F26)/3,0)) + (YEAR(G26) - YEAR(F26)) * 4 + 1, K26="per month", (MONTH(G26) - MONTH(F26)) + (YEAR(G26) - YEAR(F26)) * 12 + 1, K26="bimonthly", ROUNDUP(((MONTH(G26) - MONTH(F26)) + (YEAR(G26) - YEAR(F26)) * 12 + 1) / 2, 0), K26="per year", (YEAR(G26) - YEAR(F26)) + 1, K26="biyear", ROUNDUP(((YEAR(G26) - YEAR(F26)) + 1) / 2, 0), TRUE, "")} | M26: 9.0599564 | N26: 48.509597
A27: Dr. Simon Priess | B27: 104003 | C27: Europe | D27: Germany | H27: =IF(ISBLANK(G27), "", IF(INT(G27 - TODAY()) >= 0, "D-" & INT(G27 - TODAY()), "D+" & ABS(INT(G27 - TODAY())))) | I27: R&D Feedback | J27: R&D Feedback | K27: per year | L27: {=_xlfn.IFS(OR(ISBLANK(F27), ISBLANK(G27), ISBLANK(K27)), "", K27="per quarter", (ROUNDUP(MONTH(G27)/3,0) - ROUNDUP(MONTH(F27)/3,0)) + (YEAR(G27) - YEAR(F27)) * 4 + 1, K27="per month", (MONTH(G27) - MONTH(F27)) + (YEAR(G27) - YEAR(F27)) * 12 + 1, K27="bimonthly", ROUNDUP(((MONTH(G27) - MONTH(F27)) + (YEAR(G27) - YEAR(F27)) * 12 + 1) / 2, 0), K27="per year", (YEAR(G27) - YEAR(F27)) + 1, K27="biyear", ROUNDUP(((YEAR(G27) - YEAR(F27)) + 1) / 2, 0), TRUE, "")} | M27: 8.487449 | N27: 49.856016
A28: Dr. Simon Priess | B28: 104003 | C28: Europe | D28: Germany | H28: =IF(ISBLANK(G28), "", IF(INT(G28 - TODAY()) >= 0, "D-" & INT(G28 - TODAY()), "D+" & ABS(INT(G28 - TODAY())))) | I28: Case Report | J28: Case | K28: per year | L28: {=_xlfn.IFS(OR(ISBLANK(F28), ISBLANK(G28), ISBLANK(K28)), "", K28="per quarter", (ROUNDUP(MONTH(G28)/3,0) - ROUNDUP(MONTH(F28)/3,0)) + (YEAR(G28) - YEAR(F28)) * 4 + 1, K28="per month", (MONTH(G28) - MONTH(F28)) + (YEAR(G28) - YEAR(F28)) * 12 + 1, K28="bimonthly", ROUNDUP(((MONTH(G28) - MONTH(F28)) + (YEAR(G28) - YEAR(F28)) * 12 + 1) / 2, 0), K28="per year", (YEAR(G28) - YEAR(F28)) + 1, K28="biyear", ROUNDUP(((YEAR(G28) - YEAR(F28)) + 1) / 2, 0), TRUE, "")} | M28: 8.487449 | N28: 49.856016
A29: Dr. Simon Priess | B29: 104003 | C29: Europe | D29: Germany | H29: =IF(ISBLANK(G29), "", IF(INT(G29 - TODAY()) >= 0, "D-" & INT(G29 - TODAY()), "D+" & ABS(INT(G29 - TODAY())))) | I29: (Other) | J29: Contents creation | K29: per year | L29: {=_xlfn.IFS(OR(ISBLANK(F29), ISBLANK(G29), ISBLANK(K29)), "", K29="per quarter", (ROUNDUP(MONTH(G29)/3,0) - ROUNDUP(MONTH(F29)/3,0)) + (YEAR(G29) - YEAR(F29)) * 4 + 1, K29="per month", (MONTH(G29) - MONTH(F29)) + (YEAR(G29) - YEAR(F29)) * 12 + 1, K29="bimonthly", ROUNDUP(((MONTH(G29) - MONTH(F29)) + (YEAR(G29) - YEAR(F29)) * 12 + 1) / 2, 0), K29="per year", (YEAR(G29) - YEAR(F29)) + 1, K29="biyear", ROUNDUP(((YEAR(G29) - YEAR(F29)) + 1) / 2, 0), TRUE, "")} | M29: 8.487449 | N29: 49.856016
A30: Dr. Simon Priess | B30: 104003 | C30: Europe | D30: Germany | H30: =IF(ISBLANK(G30), "", IF(INT(G30 - TODAY()) >= 0, "D-" & INT(G30 - TODAY()), "D+" & ABS(INT(G30 - TODAY())))) | I30: Lecture | J30: Academy lectures | K30: per year | L30: {=_xlfn.IFS(OR(ISBLANK(F30), ISBLANK(G30), ISBLANK(K30)), "", K30="per quarter", (ROUNDUP(MONTH(G30)/3,0) - ROUNDUP(MONTH(F30)/3,0)) + (YEAR(G30) - YEAR(F30)) * 4 + 1, K30="per month", (MONTH(G30) - MONTH(F30)) + (YEAR(G30) - YEAR(F30)) * 12 + 1, K30="bimonthly", ROUNDUP(((MONTH(G30) - MONTH(F30)) + (YEAR(G30) - YEAR(F30)) * 12 + 1) / 2, 0), K30="per year", (YEAR(G30) - YEAR(F30)) + 1, K30="biyear", ROUNDUP(((YEAR(G30) - YEAR(F30)) + 1) / 2, 0), TRUE, "")} | M30: 8.487449 | N30: 49.856016
A31: Dr. Justinas Pletkus | B31: 105001 | C31: Europe | D31: Lithuania | H31: =IF(ISBLANK(G31), "", IF(INT(G31 - TODAY()) >= 0, "D-" & INT(G31 - TODAY()), "D+" & ABS(INT(G31 - TODAY())))) | I31: (Other) | J31: TBD By dylam | K31: per year | L31: {=_xlfn.IFS(OR(ISBLANK(F31), ISBLANK(G31), ISBLANK(K31)), "", K31="per quarter", (ROUNDUP(MONTH(G31)/3,0) - ROUNDUP(MONTH(F31)/3,0)) + (YEAR(G31) - YEAR(F31)) * 4 + 1, K31="per month", (MONTH(G31) - MONTH(F31)) + (YEAR(G31) - YEAR(F31)) * 12 + 1, K31="bimonthly", ROUNDUP(((MONTH(G31) - MONTH(F31)) + (YEAR(G31) - YEAR(F31)) * 12 + 1) / 2, 0), K31="per year", (YEAR(G31) - YEAR(F31)) + 1, K31="biyear", ROUNDUP(((YEAR(G31) - YEAR(F31)) + 1) / 2, 0), TRUE, "")} | M31: 23.881275 | N31: 55.169438
A32: Dr. Justinas Pletkus | B32: 105002 | C32: Europe | D32: Lithuania | F32: 45784 | G32: 46149 | H32: =IF(ISBLANK(G32), "", IF(INT(G32 - TODAY()) >= 0, "D-" & INT(G32 - TODAY()), "D+" & ABS(INT(G32 - TODAY())))) -> D-171 | I32: (Other) | J32: TBD By dylam | K32: per year | L32: {=_xlfn.IFS(OR(ISBLANK(F32), ISBLANK(G32), ISBLANK(K32)), "", K32="per quarter", (ROUNDUP(MONTH(G32)/3,0) - ROUNDUP(MONTH(F32)/3,0)) + (YEAR(G32) - YEAR(F32)) * 4 + 1, K32="per month", (MONTH(G32) - MONTH(F32)) + (YEAR(G32) - YEAR(F32)) * 12 + 1, K32="bimonthly", ROUNDUP(((MONTH(G32) - MONTH(F32)) + (YEAR(G32) - YEAR(F32)) * 12 + 1) / 2, 0), K32="per year", (YEAR(G32) - YEAR(F32)) + 1, K32="biyear", ROUNDUP(((YEAR(G32) - YEAR(F32)) + 1) / 2, 0), TRUE, "")} -> 2 | M32: 23.881275 | N32: 55.169438
A33: Dr. Gabriel Musetescu | B33: 106001 | C33: Europe | D33: Romania | F33: 45778 | G33: 46022 | H33: =IF(ISBLANK(G33), "", IF(INT(G33 - TODAY()) >= 0, "D-" & INT(G33 - TODAY()), "D+" & ABS(INT(G33 - TODAY())))) -> D-44 | I33: Lecture | J33: Hands-on course | K33: per year | L33: {=_xlfn.IFS(OR(ISBLANK(F33), ISBLANK(G33), ISBLANK(K33)), "", K33="per quarter", (ROUNDUP(MONTH(G33)/3,0) - ROUNDUP(MONTH(F33)/3,0)) + (YEAR(G33) - YEAR(F33)) * 4 + 1, K33="per month", (MONTH(G33) - MONTH(F33)) + (YEAR(G33) - YEAR(F33)) * 12 + 1, K33="bimonthly", ROUNDUP(((MONTH(G33) - MONTH(F33)) + (YEAR(G33) - YEAR(F33)) * 12 + 1) / 2, 0), K33="per year", (YEAR(G33) - YEAR(F33)) + 1, K33="biyear", ROUNDUP(((YEAR(G33) - YEAR(F33)) + 1) / 2, 0), TRUE, "")} -> 1 | M33: 26.102538 | N33: 44.426767
A34: Dr. Gabriel Musetescu | B34: 106001 | C34: Europe | D34: Romania | F34: 45778 | G34: 46022 | H34: =IF(ISBLANK(G34), "", IF(INT(G34 - TODAY()) >= 0, "D-" & INT(G34 - TODAY()), "D+" & ABS(INT(G34 - TODAY())))) -> D-44 | I34: Lecture | J34: Lecture | K34: per year | L34: {=_xlfn.IFS(OR(ISBLANK(F34), ISBLANK(G34), ISBLANK(K34)), "", K34="per quarter", (ROUNDUP(MONTH(G34)/3,0) - ROUNDUP(MONTH(F34)/3,0)) + (YEAR(G34) - YEAR(F34)) * 4 + 1, K34="per month", (MONTH(G34) - MONTH(F34)) + (YEAR(G34) - YEAR(F34)) * 12 + 1, K34="bimonthly", ROUNDUP(((MONTH(G34) - MONTH(F34)) + (YEAR(G34) - YEAR(F34)) * 12 + 1) / 2, 0), K34="per year", (YEAR(G34) - YEAR(F34)) + 1, K34="biyear", ROUNDUP(((YEAR(G34) - YEAR(F34)) + 1) / 2, 0), TRUE, "")} -> 1 | M34: 26.102538 | N34: 44.426767
A35: Dr. Gabriel Musetescu | B35: 106001 | C35: Europe | D35: Romania | F35: 45778 | G35: 46022 | H35: =IF(ISBLANK(G35), "", IF(INT(G35 - TODAY()) >= 0, "D-" & INT(G35 - TODAY()), "D+" & ABS(INT(G35 - TODAY())))) -> D-44 | I35: Webinar | J35: Webinar | K35: per year | L35: {=_xlfn.IFS(OR(ISBLANK(F35), ISBLANK(G35), ISBLANK(K35)), "", K35="per quarter", (ROUNDUP(MONTH(G35)/3,0) - ROUNDUP(MONTH(F35)/3,0)) + (YEAR(G35) - YEAR(F35)) * 4 + 1, K35="per month", (MONTH(G35) - MONTH(F35)) + (YEAR(G35) - YEAR(F35)) * 12 + 1, K35="bimonthly", ROUNDUP(((MONTH(G35) - MONTH(F35)) + (YEAR(G35) - YEAR(F35)) * 12 + 1) / 2, 0), K35="per year", (YEAR(G35) - YEAR(F35)) + 1, K35="biyear", ROUNDUP(((YEAR(G35) - YEAR(F35)) + 1) / 2, 0), TRUE, "")} -> 1 | M35: 26.102538 | N35: 44.426767
A36: Dr. Michalis Diomataris | B36: 107001 | C36: Europe | D36: Greece | F36: 45839 | G36: 46204 | H36: =IF(ISBLANK(G36), "", IF(INT(G36 - TODAY()) >= 0, "D-" & INT(G36 - TODAY()), "D+" & ABS(INT(G36 - TODAY())))) -> D-226 | I36: Lecture | J36: Lectures at Conference | K36: per year | L36: {=_xlfn.IFS(OR(ISBLANK(F36), ISBLANK(G36), ISBLANK(K36)), "", K36="per quarter", (ROUNDUP(MONTH(G36)/3,0) - ROUNDUP(MONTH(F36)/3,0)) + (YEAR(G36) - YEAR(F36)) * 4 + 1, K36="per month", (MONTH(G36) - MONTH(F36)) + (YEAR(G36) - YEAR(F36)) * 12 + 1, K36="bimonthly", ROUNDUP(((MONTH(G36) - MONTH(F36)) + (YEAR(G36) - YEAR(F36)) * 12 + 1) / 2, 0), K36="per year", (YEAR(G36) - YEAR(F36)) + 1, K36="biyear", ROUNDUP(((YEAR(G36) - YEAR(F36)) + 1) / 2, 0), TRUE, "")} -> 2 | M36: 23.737233 | N36: 37.982358
A37: Dr. Michalis Diomataris | B37: 107001 | C37: Europe | D37: Greece | F37: 45839 | G37: 46204 | H37: =IF(ISBLANK(G37), "", IF(INT(G37 - TODAY()) >= 0, "D-" & INT(G37 - TODAY()), "D+" & ABS(INT(G37 - TODAY())))) -> D-226 | I37: Article | J37: Article | K37: per year | L37: {=_xlfn.IFS(OR(ISBLANK(F37), ISBLANK(G37), ISBLANK(K37)), "", K37="per quarter", (ROUNDUP(MONTH(G37)/3,0) - ROUNDUP(MONTH(F37)/3,0)) + (YEAR(G37) - YEAR(F37)) * 4 + 1, K37="per month", (MONTH(G37) - MONTH(F37)) + (YEAR(G37) - YEAR(F37)) * 12 + 1, K37="bimonthly", ROUNDUP(((MONTH(G37) - MONTH(F37)) + (YEAR(G37) - YEAR(F37)) * 12 + 1) / 2, 0), K37="per year", (YEAR(G37) - YEAR(F37)) + 1, K37="biyear", ROUNDUP(((YEAR(G37) - YEAR(F37)) + 1) / 2, 0), TRUE, "")} -> 2 | M37: 23.737233 | N37: 37.982358
A38: Dr. Michalis Diomataris | B38: 107001 | C38: Europe | D38: Greece | F38: 45839 | G38: 46204 | H38: =IF(ISBLANK(G38), "", IF(INT(G38 - TODAY()) >= 0, "D-" & INT(G38 - TODAY()), "D+" & ABS(INT(G38 - TODAY())))) -> D-226 | I38: Lecture | J38: Academic content creation | K38: per year | L38: {=_xlfn.IFS(OR(ISBLANK(F38), ISBLANK(G38), ISBLANK(K38)), "", K38="per quarter", (ROUNDUP(MONTH(G38)/3,0) - ROUNDUP(MONTH(F38)/3,0)) + (YEAR(G38) - YEAR(F38)) * 4 + 1, K38="per month", (MONTH(G38) - MONTH(F38)) + (YEAR(G38) - YEAR(F38)) * 12 + 1, K38="bimonthly", ROUNDUP(((MONTH(G38) - MONTH(F38)) + (YEAR(G38) - YEAR(F38)) * 12 + 1) / 2, 0), K38="per year", (YEAR(G38) - YEAR(F38)) + 1, K38="biyear", ROUNDUP(((YEAR(G38) - YEAR(F38)) + 1) / 2, 0), TRUE, "")} -> 2 | M38: 23.737233 | N38: 37.982358
A39: Dr. Grzegorz Wasiluk | B39: 108001 | C39: Europe | D39: Poland | H39: =IF(ISBLANK(G39), "", IF(INT(G39 - TODAY()) >= 0, "D-" & INT(G39 - TODAY()), "D+" & ABS(INT(G39 - TODAY())))) | I39: R&D Feedback | J39: R&D Feedback | K39: per year | L39: {=_xlfn.IFS(OR(ISBLANK(F39), ISBLANK(G39), ISBLANK(K39)), "", K39="per quarter", (ROUNDUP(MONTH(G39)/3,0) - ROUNDUP(MONTH(F39)/3,0)) + (YEAR(G39) - YEAR(F39)) * 4 + 1, K39="per month", (MONTH(G39) - MONTH(F39)) + (YEAR(G39) - YEAR(F39)) * 12 + 1, K39="bimonthly", ROUNDUP(((MONTH(G39) - MONTH(F39)) + (YEAR(G39) - YEAR(F39)) * 12 + 1) / 2, 0), K39="per year", (YEAR(G39) - YEAR(F39)) + 1, K39="biyear", ROUNDUP(((YEAR(G39) - YEAR(F39)) + 1) / 2, 0), TRUE, "")} | M39: 21.012229 | N39: 52.229676
A40: Dr. Grzegorz Wasiluk | B40: 108001 | C40: Europe | D40: Poland | H40: =IF(ISBLANK(G40), "", IF(INT(G40 - TODAY()) >= 0, "D-" & INT(G40 - TODAY()), "D+" & ABS(INT(G40 - TODAY())))) | I40: Case Report | J40: Case | K40: per year | L40: {=_xlfn.IFS(OR(ISBLANK(F40), ISBLANK(G40), ISBLANK(K40)), "", K40="per quarter", (ROUNDUP(MONTH(G40)/3,0) - ROUNDUP(MONTH(F40)/3,0)) + (YEAR(G40) - YEAR(F40)) * 4 + 1, K40="per month", (MONTH(G40) - MONTH(F40)) + (YEAR(G40) - YEAR(F40)) * 12 + 1, K40="bimonthly", ROUNDUP(((MONTH(G40) - MONTH(F40)) + (YEAR(G40) - YEAR(F40)) * 12 + 1) / 2, 0), K40="per year", (YEAR(G40) - YEAR(F40)) + 1, K40="biyear", ROUNDUP(((YEAR(G40) - YEAR(F40)) + 1) / 2, 0), TRUE, "")} | M40: 21.012229 | N40: 52.229676
...

Sheet targets
A1: KOL | B1: Lecture | C1: Testimonial | D1: SNS Posting | E1: Case Report | F1: R&D Feedback | G1: Webinar | H1: Article
A2: Dr. Michalis Diomataris | B2: 5 | C2: 1 | D2: 1 | E2: 1 | F2: 1 | G2: 1 | H2: 1
A3: Dr. Oguz Emeklibas | B3: 4 | C3: 1 | D3: 1 | E3: 1 | F3: 1 | G3: 1 | H3: 1
A4: Dr. Grzegorz Wasiluk | B4: 4 | C4: 1 | D4: 1 | E4: 1 | F4: 1 | G4: 1 | H4: 1
A5: Dr. Sardor Mirakhmedov | B5: 4 | C5: 1 | D5: 1 | E5: 1 | F5: 1 | G5: 1 | H5: 1
A6: Dr. Łukasz Zadrożny | B6: 4 | C6: 1 | D6: 1 | E6: 1 | F6: 1 | G6: 1 | H6: 1
A7: Dr. Robert Jung | B7: 4 | C7: 1 | D7: 1 | E7: 1 | F7: 1 | G7: 1 | H7: 1
A8: Dr. Marco Tallarico | B8: 4 | C8: 1 | D8: 1 | E8: 1 | F8: 1 | G8: 1 | H8: 1
A9: Dr. Filip Rebelo | B9: 4 | C9: 1 | D9: 1 | E9: 1 | F9: 1 | G9: 1 | H9: 1
A10: Dr. Emmanuel Bocquet | B10: 4 | C10: 1 | D10: 1 | E10: 1 | F10: 1 | G10: 1 | H10: 1
A11: Dr. Alexandre Richard | B11: 4 | C11: 1 | D11: 1 | E11: 1 | F11: 1 | G11: 1 | H11: 1
A12: Dr. Gabriel Musetescu | B12: 4 | C12: 1 | D12: 1 | E12: 1 | F12: 1 | G12: 1 | H12: 1
A13: Dr. Justinas Pletkus | B13: 4 | C13: 1 | D13: 1 | E13: 1 | F13: 1 | G13: 1 | H13: 1
... A22: Dr. Mohamed Elashry | B22: 4 | C22: 1 | D22: 1 | E22: 1 | F22: 1 | G22: 1 | H22: 1

Sheet plans
A1: KOL | B1: KOL_ID | C1: Area | D1: Country | E1: Activity | F1: Planned Date | G1: Status(Planned/Reminded/Done) | H1: Notes | I1: Days Until (D-) | J1: In Contract | K1: Admin
A2: Dr. Michalis Diomataris | B2: =VLOOKUP($A2,contracts!$A$2:$L$100,2,0) -> 107001 | C2: =VLOOKUP($A2,contracts!$A$2:$L$100,3,0) -> Europe | D2: =VLOOKUP($A2,contracts!$A$2:$L$100,4,0) -> Greece | E2: Lecture | F2: 45899 | G2: Planned | I2: =IF(ISBLANK(F2), "", IF(INT(F2 - TODAY()) >= 0, "-" & INT(F2 - TODAY()), "+" & ABS(INT(F2 - TODAY())))) -> +79 | J2: {=_xlfn.IFS(OR(ISBLANK(F2), ISBLANK(G2)), "", TODAY() > G2, "Expired", TODAY() < F2, "Not Started", TRUE, "Active")} -> Active
A3: Dr. Oguz Emeklibas | B3: =VLOOKUP($A3,contracts!$A$2:$L$100,2,0) -> 104001 | C3: =VLOOKUP($A3,contracts!$A$2:$L$100,3,0) -> Europe | D3: =VLOOKUP($A3,contracts!$A$2:$L$100,4,0) -> Germany | E3: Lecture | F3: 45955 | G3: Planned | H3: Vanest Launching Show | I3: =IF(ISBLANK(F3), "", IF(INT(F3 - TODAY()) >= 0, "-" & INT(F3 - TODAY()), "+" & ABS(INT(F3 - TODAY())))) -> +23 | J3: {=_xlfn.IFS(OR(ISBLANK(F3), ISBLANK(G3)), "", TODAY() > G3, "Expired", TODAY() < F3, "Not Started", TRUE, "Active")} -> Active
A4: Dr. Grzegorz Wasiluk | B4: =VLOOKUP($A4,contracts!$A$2:$L$100,2,0) -> 108001 | C4: =VLOOKUP($A4,contracts!$A$2:$L$100,3,0) -> Europe | D4: =VLOOKUP($A4,contracts!$A$2:$L$100,4,0) -> Poland | E4: Testimonial | F4: 45949 | G4: Planned | I4: =IF(ISBLANK(F4), "", IF(INT(F4 - TODAY()) >= 0, "-" & INT(F4 - TODAY()), "+" & ABS(INT(F4 - TODAY())))) -> +29 | J4: {=_xlfn.IFS(OR(ISBLANK(F4), ISBLANK(G4)), "", TODAY() > G4, "Expired", TODAY() < F4, "Not Started", TRUE, "Active")} -> Active
A5: Dr. Sardor Mirakhmedov | B5: =VLOOKUP($A5,contracts!$A$2:$L$100,2,0) -> 206001 | C5: =VLOOKUP($A5,contracts!$A$2:$L$100,3,0) -> APAC | D5: =VLOOKUP($A5,contracts!$A$2:$L$100,4,0) -> Uzbekistan | E5: Lecture | F5: 45917 | G5: Planned | I5: =IF(ISBLANK(F5), "", IF(INT(F5 - TODAY()) >= 0, "-" & INT(F5 - TODAY()), "+" & ABS(INT(F5 - TODAY())))) -> +61 | J5: {=_xlfn.IFS(OR(ISBLANK(F5), ISBLANK(G5)), "", TODAY() > G5, "Expired", TODAY() < F5, "Not Started", TRUE, "Active")} -> Active
A6: Dr. Łukasz Zadrożny | B6: =VLOOKUP($A6,contracts!$A$2:$L$100,2,0) -> 108003 | C6: =VLOOKUP($A6,contracts!$A$2:$L$100,3,0) -> Europe | D6: =VLOOKUP($A6,contracts!$A$2:$L$100,4,0) -> Poland | I6: =IF(ISBLANK(F6), "", IF(INT(F6 - TODAY()) >= 0, "-" & INT(F6 - TODAY()), "+" & ABS(INT(F6 - TODAY())))) | J6: {=_xlfn.IFS(OR(ISBLANK(F6), ISBLANK(G6)), "", TODAY() > G6, "Expired", TODAY() < F6, "Not Started", TRUE, "Active")}
A7: Dr. Robert Jung | B7: =VLOOKUP($A7,contracts!$A$2:$L$100,2,0) -> 101001 | C7: =VLOOKUP($A7,contracts!$A$2:$L$100,3,0) -> Europe | D7: =VLOOKUP($A7,contracts!$A$2:$L$100,4,0) -> UK | E7: Academy | F7: 45899 | G7: Planned | I7: =IF(ISBLANK(F7), "", IF(INT(F7 - TODAY()) >= 0, "-" & INT(F7 - TODAY()), "+" & ABS(INT(F7 - TODAY())))) -> +79 | J7: {=_xlfn.IFS(OR(ISBLANK(F7), ISBLANK(G7)), "", TODAY() > G7, "Expired", TODAY() < F7, "Not Started", TRUE, "Active")} -> Active
A8: Dr. Marco Tallarico | B8: =VLOOKUP($A8,contracts!$A$2:$L$100,2,0) -> 111001 | C8: =VLOOKUP($A8,contracts!$A$2:$L$100,3,0) -> Europe | D8: =VLOOKUP($A8,contracts!$A$2:$L$100,4,0) -> Italy | I8: =IF(ISBLANK(F8), "", IF(INT(F8 - TODAY()) >= 0, "-" & INT(F8 - TODAY()), "+" & ABS(INT(F8 - TODAY())))) | J8: {=_xlfn.IFS(OR(ISBLANK(F8), ISBLANK(G8)), "", TODAY() > G8, "Expired", TODAY() < F8, "Not Started", TRUE, "Active")}
A9: Dr. Filip Rebelo | B9: =VLOOKUP($A9,contracts!$A$2:$L$100,2,0) -> 102001 | C9: =VLOOKUP($A9,contracts!$A$2:$L$100,3,0) -> Europe | D9: =VLOOKUP($A9,contracts!$A$2:$L$100,4,0) -> Sweden | E9: Hands-on | F9: 45898 | G9: Planned | I9: =IF(ISBLANK(F9), "", IF(INT(F9 - TODAY()) >= 0, "-" & INT(F9 - TODAY()), "+" & ABS(INT(F9 - TODAY())))) -> +80 | J9: {=_xlfn.IFS(OR(ISBLANK(F9), ISBLANK(G9)), "", TODAY() > G9, "Expired", TODAY() < F9, "Not Started", TRUE, "Active")} -> Active
A10: Dr. Emmanuel Bocquet | B10: =VLOOKUP($A10,contracts!$A$2:$L$100,2,0) -> 103004 | C10: =VLOOKUP($A10,contracts!$A$2:$L$100,3,0) -> Europe | D10: =VLOOKUP($A10,contracts!$A$2:$L$100,4,0) -> France | E10: Lecture | F10: 45975 | G10: Planned | H10: ADF 2025 | I10: =IF(ISBLANK(F10), "", IF(INT(F10 - TODAY()) >= 0, "-" & INT(F10 - TODAY()), "+" & ABS(INT(F10 - TODAY())))) -> +3 | J10: {=_xlfn.IFS(OR(ISBLANK(F10), ISBLANK(G10)), "", TODAY() > G10, "Expired", TODAY() < F10, "Not Started", TRUE, "Active")} -> Active
A11: Dr. Emmanuel Bocquet | B11: =VLOOKUP($A11,contracts!$A$2:$L$100,2,0) -> 103004 | C11: =VLOOKUP($A11,contracts!$A$2:$L$100,3,0) -> Europe | D11: =VLOOKUP($A11,contracts!$A$2:$L$100,4,0) -> France | E11: Lecture | F11: 45962 | G11: Planned | I11: =IF(ISBLANK(F11), "", IF(INT(F11 - TODAY()) >= 0, "-" & INT(F11 - TODAY()), "+" & ABS(INT(F11 - TODAY())))) -> +16 | J11: {=_xlfn.IFS(OR(ISBLANK(F11), ISBLANK(G11)), "", TODAY() > G11, "Expired", TODAY() < F11, "Not Started", TRUE, "Active")} -> Active
A12: Dr. Alexandre Richard | B12: =VLOOKUP($A12,contracts!$A$2:$L$100,2,0) -> 103001 | C12: =VLOOKUP($A12,contracts!$A$2:$L$100,3,0) -> Europe | D12: =VLOOKUP($A12,contracts!$A$2:$L$100,4,0) -> France | E12: Lecture | F12: 46000 | G12: Planned | I12: =IF(ISBLANK(F12), "", IF(INT(F12 - TODAY()) >= 0, "-" & INT(F12 - TODAY()), "+" & ABS(INT(F12 - TODAY())))) -> -22 | J12: {=_xlfn.IFS(OR(ISBLANK(F12), ISBLANK(G12)), "", TODAY() > G12, "Expired", TODAY() < F12, "Not Started", TRUE, "Active")} -> Not Started
A13: Dr. Gabriel Musetescu | B13: =VLOOKUP($A13,contracts!$A$2:$L$100,2,0) -> 106001 | C13: =VLOOKUP($A13,contracts!$A$2:$L$100,3,0) -> Europe | D13: =VLOOKUP($A13,contracts!$A$2:$L$100,4,0) -> Romania | E13: SNS Posting | F13: 45930 | G13: Planned | I13: =IF(ISBLANK(F13), "", IF(INT(F13 - TODAY()) >= 0, "-" & INT(F13 - TODAY()), "+" & ABS(INT(F13 - TODAY())))) -> +48 | J13: {=_xlfn.IFS(OR(ISBLANK(F13), ISBLANK(G13)), "", TODAY() > G13, "Expired", TODAY() < F13, "Not Started", TRUE, "Active")} -> Active
A14: Dr. Justinas Pletkus | B14: =VLOOKUP($A14,contracts!$A$2:$L$100,2,0) -> 105001 | C14: =VLOOKUP($A14,contracts!$A$2:$L$100,3,0) -> Europe | D14: =VLOOKUP($A14,contracts!$A$2:$L$100,4,0) -> Lithuania | I14: =IF(ISBLANK(F14), "", IF(INT(F14 - TODAY()) >= 0, "-" & INT(F14 - TODAY()), "+" & ABS(INT(F14 - TODAY())))) | J14: {=_xlfn.IFS(OR(ISBLANK(F14), ISBLANK(G14)), "", TODAY() > G14, "Expired", TODAY() < F14, "Not Started", TRUE, "Active")}
A15: Dr. Anton Sadovnyshyi | B15: =VLOOKUP($A15,contracts!$A$2:$L$100,2,0) -> 109001 | C15: =VLOOKUP($A15,contracts!$A$2:$L$100,3,0) -> Europe | D15: =VLOOKUP($A15,contracts!$A$2:$L$100,4,0) -> Ukraine | E15: Testimonial | F15: 46031 | G15: Planned | I15: =IF(ISBLANK(F15), "", IF(INT(F15 - TODAY()) >= 0, "-" & INT(F15 - TODAY()), "+" & ABS(INT(F15 - TODAY())))) -> -53 | J15: {=_xlfn.IFS(OR(ISBLANK(F15), ISBLANK(G15)), "", TODAY() > G15, "Expired", TODAY() < F15, "Not Started", TRUE, "Active")} -> Not Started
A16: Dr. Yevhenii Sluchevskyi | B16: =VLOOKUP($A16,contracts!$A$2:$L$100,2,0) -> 109002 | C16: =VLOOKUP($A16,contracts!$A$2:$L$100,3,0) -> Europe | D16: =VLOOKUP($A16,contracts!$A$2:$L$100,4,0) -> Ukraine | E16: Academy | F16: 45899 | G16: Planned | I16: =IF(ISBLANK(F16), "", IF(INT(F16 - TODAY()) >= 0, "-" & INT(F16 - TODAY()), "+" & ABS(INT(F16 - TODAY())))) -> +79 | J16: {=_xlfn.IFS(OR(ISBLANK(F16), ISBLANK(G16)), "", TODAY() > G16, "Expired", TODAY() < F16, "Not Started", TRUE, "Active")} -> Active
A17: Dr. Manapat Thaveeprungsiporn | B17: =VLOOKUP($A17,contracts!$A$2:$L$100,2,0) -> 205001 | C17: =VLOOKUP($A17,contracts!$A$2:$L$100,3,0) -> APAC | D17: =VLOOKUP($A17,contracts!$A$2:$L$100,4,0) -> Thailand | I17: =IF(ISBLANK(F17), "", IF(INT(F17 - TODAY()) >= 0, "-" & INT(F17 - TODAY()), "+" & ABS(INT(F17 - TODAY())))) | J17: {=_xlfn.IFS(OR(ISBLANK(F17), ISBLANK(G17)), "", TODAY() > G17, "Expired", TODAY() < F17, "Not Started", TRUE, "Active")}
A18: Dr. Sapaar Bayarmagnai | B18: =VLOOKUP($A18,contracts!$A$2:$L$100,2,0) -> 202001 | C18: =VLOOKUP($A18,contracts!$A$2:$L$100,3,0) -> APAC | D18: =VLOOKUP($A18,contracts!$A$2:$L$100,4,0) -> Mongolia | E18: Lecture | F18: 46031 | G18: Planned | I18: =IF(ISBLANK(F18), "", IF(INT(F18 - TODAY()) >= 0, "-" & INT(F18 - TODAY()), "+" & ABS(INT(F18 - TODAY())))) -> -53 | J18: {=_xlfn.IFS(OR(ISBLANK(F18), ISBLANK(G18)), "", TODAY() > G18, "Expired", TODAY() < F18, "Not Started", TRUE, "Active")} -> Not Started
A19: Dr. Priyam Aditya | B19: =VLOOKUP($A19,contracts!$A$2:$L$100,2,0) -> 203002 | C19: =VLOOKUP($A19,contracts!$A$2:$L$100,3,0) -> APAC | D19: =VLOOKUP($A19,contracts!$A$2:$L$100,4,0) -> India | E19: Lecture | F19: 45930 | G19: Planned | I19: =IF(ISBLANK(F19), "", IF(INT(F19 - TODAY()) >= 0, "-" & INT(F19 - TODAY()), "+" & ABS(INT(F19 - TODAY())))) -> +48 | J19: {=_xlfn.IFS(OR(ISBLANK(F19), ISBLANK(G19)), "", TODAY() > G19, "Expired", TODAY() < F19, "Not Started", TRUE, "Active")} -> Active
A20: Dr. Ahmad Al Hassiny | B20: =VLOOKUP($A20,contracts!$A$2:$L$100,2,0) -> 204001 | C20: =VLOOKUP($A20,contracts!$A$2:$L$100,3,0) -> APAC | D20: =VLOOKUP($A20,contracts!$A$2:$L$100,4,0) -> New Zealand | I20: =IF(ISBLANK(F20), "", IF(INT(F20 - TODAY()) >= 0, "-" & INT(F20 - TODAY()), "+" & ABS(INT(F20 - TODAY())))) | J20: {=_xlfn.IFS(OR(ISBLANK(F20), ISBLANK(G20)), "", TODAY() > G20, "Expired", TODAY() < F20, "Not Started", TRUE, "Active")}
A21: Dr. Sameh Shaaban | B21: =VLOOKUP($A21,contracts!$A$2:$L$100,2,0) -> 301001 | C21: =VLOOKUP($A21,contracts!$A$2:$L$100,3,0) -> MEA | D21: =VLOOKUP($A21,contracts!$A$2:$L$100,4,0) -> Egypt | E21: Testimonial | F21: 45949 | G21: Planned | I21: =IF(ISBLANK(F21), "", IF(INT(F21 - TODAY()) >= 0, "-" & INT(F21 - TODAY()), "+" & ABS(INT(F21 - TODAY())))) -> +29 | J21: {=_xlfn.IFS(OR(ISBLANK(F21), ISBLANK(G21)), "", TODAY() > G21, "Expired", TODAY() < F21, "Not Started", TRUE, "Active")} -> Active
A22: Dr. Amr Elkhadem | B22: =VLOOKUP($A22,contracts!$A$2:$L$100,2,0) -> 301002 | C22: =VLOOKUP($A22,contracts!$A$2:$L$100,3,0) -> MEA | D22: =VLOOKUP($A22,contracts!$A$2:$L$100,4,0) -> Egypt | E22: SNS Posting | F22: 46031 | G22: Planned | I22: =IF(ISBLANK(F22), "", IF(INT(F22 - TODAY()) >= 0, "-" & INT(F22 - TODAY()), "+" & ABS(INT(F22 - TODAY())))) -> -53 | J22: {=_xlfn.IFS(OR(ISBLANK(F22), ISBLANK(G22)), "", TODAY() > G22, "Expired", TODAY() < F22, "Not Started", TRUE, "Active")} -> Not Started
A23: Dr. Mohamed Elashry | B23: =VLOOKUP($A23,contracts!$A$2:$L$100,2,0) -> 301003 | C23: =VLOOKUP($A23,contracts!$A$2:$L$100,3,0) -> MEA | D23: =VLOOKUP($A23,contracts!$A$2:$L$100,4,0) -> Egypt | E23: Academy | F23: 46031 | G23: Planned | I23: =IF(ISBLANK(F23), "", IF(INT(F23 - TODAY()) >= 0, "-" & INT(F23 - TODAY()), "+" & ABS(INT(F23 - TODAY())))) -> -53 | J23: {=_xlfn.IFS(OR(ISBLANK(F23), ISBLANK(G23)), "", TODAY() > G23, "Expired", TODAY() < F23, "Not Started", TRUE, "Active")} -> Not Started
I24: =IF(F24="","",F24-TODAY()) | J24: =IF(OR(F24="",A24=""),"",AND(F24>=INDEX([1]Contracts!$B:$B, MATCH(A24, [1]Contracts!$A:$A, 0)), F24<=INDEX([1]Contracts!$C:$C, MATCH(A24, [1]Contracts!$A:$A, 0))))
I25: =IF(F25="","",F25-TODAY()) | J25: =IF(OR(F25="",A25=""),"",AND(F25>=INDEX([1]Contracts!$B:$B, MATCH(A25, [1]Contracts!$A:$A, 0)), F25<=INDEX([1]Contracts!$C:$C, MATCH(A25, [1]Contracts!$A:$A, 0))))
I26: =IF(F26="","",F26-TODAY()) | J26: =IF(OR(F26="",A26=""),"",AND(F26>=INDEX([1]Contracts!$B:$B, MATCH(A26, [1]Contracts!$A:$A, 0)), F26<=INDEX([1]Contracts!$C:$C, MATCH(A26, [1]Contracts!$A:$A, 0))))
I27: =IF(F27="","",F27-TODAY()) | J27: =IF(OR(F27="",A27=""),"",AND(F27>=INDEX([1]Contracts!$B:$B, MATCH(A27, [1]Contracts!$A:$A, 0)), F27<=INDEX([1]Contracts!$C:$C, MATCH(A27, [1]Contracts!$A:$A, 0))))
I28: =IF(F28="","",F28-TODAY()) | J28: =IF(OR(F28="",A28=""),"",AND(F28>=INDEX([1]Contracts!$B:$B, MATCH(A28, [1]Contracts!$A:$A, 0)), F28<=INDEX([1]Contracts!$C:$C, MATCH(A28, [1]Contracts!$A:$A, 0))))
I29: =IF(F29="","",F29-TODAY()) | J29: =IF(OR(F29="",A29=""),"",AND(F29>=INDEX([1]Contracts!$B:$B, MATCH(A29, [1]Contracts!$A:$A, 0)), F29<=INDEX([1]Contracts!$C:$C, MATCH(A29, [1]Contracts!$A:$A, 0))))
I30: =IF(F30="","",F30-TODAY()) | J30: =IF(OR(F30="",A30=""),"",AND(F30>=INDEX([1]Contracts!$B:$B, MATCH(A30, [1]Contracts!$A:$A, 0)), F30<=INDEX([1]Contracts!$C:$C, MATCH(A30, [1]Contracts!$A:$A, 0))))
I31: =IF(F31="","",F31-TODAY()) | J31: =IF(OR(F31="",A31=""),"",AND(F31>=INDEX([1]Contracts!$B:$B, MATCH(A31, [1]Contracts!$A:$A, 0)), F31<=INDEX([1]Contracts!$C:$C, MATCH(A31, [1]Contracts!$A:$A, 0))))
I32: =IF(F32="","",F32-TODAY()) | J32: =IF(OR(F32="",A32=""),"",AND(F32>=INDEX([1]Contracts!$B:$B, MATCH(A32, [1]Contracts!$A:$A, 0)), F32<=INDEX([1]Contracts!$C:$C, MATCH(A32, [1]Contracts!$A:$A, 0))))
I33: =IF(F33="","",F33-TODAY()) | J33: =IF(OR(F33="",A33=""),"",AND(F33>=INDEX([1]Contracts!$B:$B, MATCH(A33, [1]Contracts!$A:$A, 0)), F33<=INDEX([1]Contracts!$C:$C, MATCH(A33, [1]Contracts!$A:$A, 0))))
I34: =IF(F34="","",F34-TODAY()) | J34: =IF(OR(F34="",A34=""),"",AND(F34>=INDEX([1]Contracts!$B:$B, MATCH(A34, [1]Contracts!$A:$A, 0)), F34<=INDEX([1]Contracts!$C:$C, MATCH(A34, [1]Contracts!$A:$A, 0))))
I35: =IF(F35="","",F35-TODAY()) | J35: =IF(OR(F35="",A35=""),"",AND(F35>=INDEX([1]Contracts!$B:$B, MATCH(A35, [1]Contracts!$A:$A, 0)), F35<=INDEX([1]Contracts!$C:$C, MATCH(A35, [1]Contracts!$A:$A, 0))))
... I1007: =IF(F1007="","",F1007-TODAY()) | J1007: =IF(OR(F1007="",A1007=""),"",AND(F1007>=INDEX([1]Contracts!$B:$B, MATCH(A1007, [1]Contracts!$A:$A, 0)), F1007<=INDEX([1]Contracts!$C:$C, MATCH(A1007, [1]Contracts!$A:$A, 0))))

Sheet tracking
A1: Name | B1: KOL_ID | C1: Area | D1: Country | E1: Quarter | F1: Month | G1: Week | H1: Activity | I1: Count
A2: Dr. Robert Jung | B2: =VLOOKUP($A2,contracts!$A$2:$L$100,2,0) -> 101001 | C2: =VLOOKUP($A2,contracts!$A$2:$L$100,3,0) -> Europe | D2: =VLOOKUP($A2,contracts!$A$2:$L$100,4,0) -> UK | E2: {=_xlfn.IFS(ISBLANK(F2), "", OR(F2="Jan", F2="Feb", F2="Mar"), "Q1", OR(F2="April", F2="May", F2="June"), "Q2", OR(F2="July", F2="August", F2="September"), "Q3", OR(F2="October", F2="November", F2="December"), "Q4", TRUE, "")} -> Q2 | F2: April | G2: 2w | H2: Contract
A3: Dr. Robert Jung | B3: =VLOOKUP($A3,contracts!$A$2:$L$100,2,0) -> 101001 | C3: =VLOOKUP($A3,contracts!$A$2:$L$100,3,0) -> Europe | D3: =VLOOKUP($A3,contracts!$A$2:$L$100,4,0) -> UK | E3: {=_xlfn.IFS(ISBLANK(F3), "", OR(F3="Jan", F3="Feb", F3="Mar"), "Q1", OR(F3="April", F3="May", F3="June"), "Q2", OR(F3="July", F3="August", F3="September"), "Q3", OR(F3="October", F3="November", F3="December"), "Q4", TRUE, "")} -> Q2 | F3: May | G3: 3w | H3: Lecture
A4: Dr. Robert Jung | B4: =VLOOKUP($A4,contracts!$A$2:$L$100,2,0) -> 101001 | C4: =VLOOKUP($A4,contracts!$A$2:$L$100,3,0) -> Europe | D4: =VLOOKUP($A4,contracts!$A$2:$L$100,4,0) -> UK | E4: {=_xlfn.IFS(ISBLANK(F4), "", OR(F4="Jan", F4="Feb", F4="Mar"), "Q1", OR(F4="April", F4="May", F4="June"), "Q2", OR(F4="July", F4="August", F4="September"), "Q3", OR(F4="October", F4="November", F4="December"), "Q4", TRUE, "")} -> Q3 | F4: July | G4: 1w | H4: MOS Test
A5: Dr. Robert Jung | B5: =VLOOKUP($A5,contracts!$A$2:$L$100,2,0) -> 101001 | C5: =VLOOKUP($A5,contracts!$A$2:$L$100,3,0) -> Europe | D5: =VLOOKUP($A5,contracts!$A$2:$L$100,4,0) -> UK | E5: {=_xlfn.IFS(ISBLANK(F5), "", OR(F5="Jan", F5="Feb", F5="Mar"), "Q1", OR(F5="April", F5="May", F5="June"), "Q2", OR(F5="July", F5="August", F5="September"), "Q3", OR(F5="October", F5="November", F5="December"), "Q4", TRUE, "")} -> Q3 | F5: August | G5: 4w | H5: i900MTest
A6: Dr. Robert Jung | B6: =VLOOKUP($A6,contracts!$A$2:$L$100,2,0) -> 101001 | C6: =VLOOKUP($A6,contracts!$A$2:$L$100,3,0) -> Europe | D6: =VLOOKUP($A6,contracts!$A$2:$L$100,4,0) -> UK | E6: {=_xlfn.IFS(ISBLANK(F6), "", OR(F6="Jan", F6="Feb", F6="Mar"), "Q1", OR(F6="April", F6="May", F6="June"), "Q2", OR(F6="July", F6="August", F6="September"), "Q3", OR(F6="October", F6="November", F6="December"), "Q4", TRUE, "")} -> Q3 | F6: September | G6: 3w | H6: Auraview Test
A7: Dr. Robert Jung | B7: =VLOOKUP($A7,contracts!$A$2:$L$100,2,0) -> 101001 | C7: =VLOOKUP($A7,contracts!$A$2:$L$100,3,0) -> Europe | D7: =VLOOKUP($A7,contracts!$A$2:$L$100,4,0) -> UK | E7: {=_xlfn.IFS(ISBLANK(F7), "", OR(F7="Jan", F7="Feb", F7="Mar"), "Q1", OR(F7="April", F7="May", F7="June"), "Q2", OR(F7="July", F7="August", F7="September"), "Q3", OR(F7="October", F7="November", F7="December"), "Q4", TRUE, "")} -> Q4 | F7: October | G7: 4w | H7: Lecture
A8: Dr. Filip Rebelo | B8: =VLOOKUP($A8,contracts!$A$2:$L$100,2,0) -> 102001 | C8: =VLOOKUP($A8,contracts!$A$2:$L$100,3,0) -> Europe | D8: =VLOOKUP($A8,contracts!$A$2:$L$100,4,0) -> Sweden | E8: {=_xlfn.IFS(ISBLANK(F8), "", OR(F8="Jan", F8="Feb", F8="Mar"), "Q1", OR(F8="April", F8="May", F8="June"), "Q2", OR(F8="July", F8="August", F8="September"), "Q3", OR(F8="October", F8="November", F8="December"), "Q4", TRUE, "")} -> Q2 | F8: April | G8: 2w | H8: Contract
A9: Dr. Filip Rebelo | B9: =VLOOKUP($A9,contracts!$A$2:$L$100,2,0) -> 102001 | C9: =VLOOKUP($A9,contracts!$A$2:$L$100,3,0) -> Europe | D9: =VLOOKUP($A9,contracts!$A$2:$L$100,4,0) -> Sweden | E9: {=_xlfn.IFS(ISBLANK(F9), "", OR(F9="Jan", F9="Feb", F9="Mar"), "Q1", OR(F9="April", F9="May", F9="June"), "Q2", OR(F9="July", F9="August", F9="September"), "Q3", OR(F9="October", F9="November", F9="December"), "Q4", TRUE, "")} -> Q2 | F9: April | G9: 3w | H9: i900c shipment
A10: Dr. Filip Rebelo | B10: =VLOOKUP($A10,contracts!$A$2:$L$100,2,0) -> 102001 | C10: =VLOOKUP($A10,contracts!$A$2:$L$100,3,0) -> Europe | D10: =VLOOKUP($A10,contracts!$A$2:$L$100,4,0) -> Sweden | E10: {=_xlfn.IFS(ISBLANK(F10), "", OR(F10="Jan", F10="Feb", F10="Mar"), "Q1", OR(F10="April", F10="May", F10="June"), "Q2", OR(F10="July", F10="August", F10="September"), "Q3", OR(F10="October", F10="November", F10="December"), "Q4", TRUE, "")} -> Q2 | F10: May | G10: 1w | H10: Contents creation
A11: Dr. Filip Rebelo | B11: =VLOOKUP($A11,contracts!$A$2:$L$100,2,0) -> 102001 | C11: =VLOOKUP($A11,contracts!$A$2:$L$100,3,0) -> Europe | D11: =VLOOKUP($A11,contracts!$A$2:$L$100,4,0) -> Sweden | E11: {=_xlfn.IFS(ISBLANK(F11), "", OR(F11="Jan", F11="Feb", F11="Mar"), "Q1", OR(F11="April", F11="May", F11="June"), "Q2", OR(F11="July", F11="August", F11="September"), "Q3", OR(F11="October", F11="November", F11="December"), "Q4", TRUE, "")} -> Q2 | F11: May | G11: 4w | H11: Lecture
A12: Dr. Alexandre Richard | B12: =VLOOKUP($A12,contracts!$A$2:$L$100,2,0) -> 103001 | C12: =VLOOKUP($A12,contracts!$A$2:$L$100,3,0) -> Europe | D12: =VLOOKUP($A12,contracts!$A$2:$L$100,4,0) -> France | E12: {=_xlfn.IFS(ISBLANK(F12), "", OR(F12="Jan", F12="Feb", F12="Mar"), "Q1", OR(F12="April", F12="May", F12="June"), "Q2", OR(F12="July", F12="August", F12="September"), "Q3", OR(F12="October", F12="November", F12="December"), "Q4", TRUE, "")} -> Q2 | F12: April | G12: 4w | H12: Contract
A13: Dr. Alexandre Richard | B13: =VLOOKUP($A13,contracts!$A$2:$L$100,2,0) -> 103001 | C13: =VLOOKUP($A13,contracts!$A$2:$L$100,3,0) -> Europe | D13: =VLOOKUP($A13,contracts!$A$2:$L$100,4,0) -> France | E13: {=_xlfn.IFS(ISBLANK(F13), "", OR(F13="Jan", F13="Feb", F13="Mar"), "Q1", OR(F13="April", F13="May", F13="June"), "Q2", OR(F13="July", F13="August", F13="September"), "Q3", OR(F13="October", F13="November", F13="December"), "Q4", TRUE, "")} -> Q2 | F13: May | G13: 4w | H13: i900 shipment
... A138: Dr. Derek Mahonny | B138: =VLOOKUP($A138,contracts!$A$2:$L$100,2,0) -> #N/A | C138: =VLOOKUP($A138,contracts!$A$2:$L$100,3,0) -> #N/A | D138: =VLOOKUP($A138,contracts!$A$2:$L$100,4,0) -> #N/A | E138: {=_xlfn.IFS(ISBLANK(F138), "", OR(F138="Jan", F138="Feb", F138="Mar"), "Q1", OR(F138="April", F138="May", F138="June"), "Q2", OR(F138="July", F138="August", F138="September"), "Q3", OR(F138="October", F138="November", F138="December"), "Q4", TRUE, "")} -> Q4 | F138: December | G138: 5w | H138: case report
